[2021-03-23 19:55:40,355] [ERROR] => Positions is not saved Cannot assign "'2'": "Positions.mol" must be a "Persons" instance.
[2021-03-23 19:56:39,022] [ERROR] => Positions is not saved Cannot assign "2": "Positions.mol" must be a "Persons" instance.
[2021-03-23 19:59:45,368] [INFO] => Сохранено в базе 451, БАТАРЕЙКИ LR03 MAX ENERGIZER AA, 32
[2021-03-23 19:59:45,370] [INFO] => записана операция с нулевым изменением количества, тип 5, vvod_info_pos
[2021-03-27 00:00:39,749] [INFO] => Есть в базе БАТАРЕЙКИ LR03 MAX ENERGIZER AA
[2021-03-27 00:00:39,831] [WARNING] => Not Found: /favicon.ico
[2021-03-27 00:10:23,476] [INFO] => Есть в базе БАТАРЕЙКИ LR03 MAX ENERGIZER AA
[2021-04-04 13:55:05,696] [INFO] => C:\Users\Win10_Game_OS\PycharmProjects\sklad_site\Positions\views.py changed, reloading.
[2021-04-04 14:00:57,453] [INFO] => Выбрано 5 позиций
[2021-04-04 14:01:33,208] [INFO] => C:\Users\Win10_Game_OS\PycharmProjects\sklad_site\Positions\views.py changed, reloading.
[2021-04-04 14:01:37,830] [INFO] => По запросу <class 'str'> позиций не найдено
[2021-04-04 14:02:06,736] [INFO] => C:\Users\Win10_Game_OS\PycharmProjects\sklad_site\Positions\views.py changed, reloading.
[2021-04-04 14:04:50,652] [INFO] => По запросу <class 'str'> позиций не найдено
[2021-04-04 14:07:09,075] [INFO] => C:\Users\Win10_Game_OS\PycharmProjects\sklad_site\Positions\views.py changed, reloading.
[2021-04-04 14:07:21,038] [INFO] => По запросу <class 'str'> позиций не найдено
[2021-04-04 14:08:02,151] [INFO] => C:\Users\Win10_Game_OS\PycharmProjects\sklad_site\Positions\views.py changed, reloading.
[2021-04-04 14:08:16,077] [INFO] => Выбрано 21 позиций
[2021-04-04 14:08:31,547] [INFO] => Выбрано 2 позиций
[2021-04-04 14:08:38,196] [INFO] => Выбрано 5 позиций
[2021-04-04 14:11:00,632] [INFO] => По запросу <class 'str'> позиций не найдено
[2021-04-04 14:11:00,672] [ERROR] => Internal Server Error: /list/
Traceback (most recent call last):
  File "C:\ProgramData\Anaconda3\envs\tuPiM\lib\site-packages\django\core\handlers\exception.py", line 47, in inner
    response = get_response(request)
  File "C:\ProgramData\Anaconda3\envs\tuPiM\lib\site-packages\django\core\handlers\base.py", line 181, in _get_response
    response = wrapped_callback(request, *callback_args, **callback_kwargs)
  File "C:\ProgramData\Anaconda3\envs\tuPiM\lib\site-packages\django\views\generic\base.py", line 70, in view
    return self.dispatch(request, *args, **kwargs)
  File "C:\ProgramData\Anaconda3\envs\tuPiM\lib\site-packages\django\views\generic\base.py", line 98, in dispatch
    return handler(request, *args, **kwargs)
  File "C:\Users\Win10_Game_OS\PycharmProjects\sklad_site\Positions\views.py", line 64, in post
    positions = positions.exce(quantity=0).exclude(quantity=None)
AttributeError: 'HttpResponse' object has no attribute 'exce'
[2021-04-04 14:11:15,183] [INFO] => По запросу <class 'str'> позиций не найдено
[2021-04-04 14:11:15,214] [ERROR] => Internal Server Error: /list/
Traceback (most recent call last):
  File "C:\ProgramData\Anaconda3\envs\tuPiM\lib\site-packages\django\core\handlers\exception.py", line 47, in inner
    response = get_response(request)
  File "C:\ProgramData\Anaconda3\envs\tuPiM\lib\site-packages\django\core\handlers\base.py", line 181, in _get_response
    response = wrapped_callback(request, *callback_args, **callback_kwargs)
  File "C:\ProgramData\Anaconda3\envs\tuPiM\lib\site-packages\django\views\generic\base.py", line 70, in view
    return self.dispatch(request, *args, **kwargs)
  File "C:\ProgramData\Anaconda3\envs\tuPiM\lib\site-packages\django\views\generic\base.py", line 98, in dispatch
    return handler(request, *args, **kwargs)
  File "C:\Users\Win10_Game_OS\PycharmProjects\sklad_site\Positions\views.py", line 64, in post
    positions = positions.exce(quantity=0).exclude(quantity=None)
AttributeError: 'HttpResponse' object has no attribute 'exce'
[2021-04-04 14:11:24,499] [INFO] => Выбрано 5 позиций
[2021-04-04 14:11:24,531] [ERROR] => Internal Server Error: /list/
Traceback (most recent call last):
  File "C:\ProgramData\Anaconda3\envs\tuPiM\lib\site-packages\django\core\handlers\exception.py", line 47, in inner
    response = get_response(request)
  File "C:\ProgramData\Anaconda3\envs\tuPiM\lib\site-packages\django\core\handlers\base.py", line 181, in _get_response
    response = wrapped_callback(request, *callback_args, **callback_kwargs)
  File "C:\ProgramData\Anaconda3\envs\tuPiM\lib\site-packages\django\views\generic\base.py", line 70, in view
    return self.dispatch(request, *args, **kwargs)
  File "C:\ProgramData\Anaconda3\envs\tuPiM\lib\site-packages\django\views\generic\base.py", line 98, in dispatch
    return handler(request, *args, **kwargs)
  File "C:\Users\Win10_Game_OS\PycharmProjects\sklad_site\Positions\views.py", line 64, in post
    positions = positions.exce(quantity=0).exclude(quantity=None)
AttributeError: 'QuerySet' object has no attribute 'exce'
[2021-04-04 14:11:50,423] [INFO] => C:\Users\Win10_Game_OS\PycharmProjects\sklad_site\Positions\views.py changed, reloading.
[2021-04-04 14:11:54,551] [INFO] => Выбрано 5 позиций
[2021-04-04 14:11:58,768] [INFO] => По запросу <class 'str'> позиций не найдено
[2021-04-04 14:11:58,819] [ERROR] => Internal Server Error: /list/
Traceback (most recent call last):
  File "C:\ProgramData\Anaconda3\envs\tuPiM\lib\site-packages\django\core\handlers\exception.py", line 47, in inner
    response = get_response(request)
  File "C:\ProgramData\Anaconda3\envs\tuPiM\lib\site-packages\django\core\handlers\base.py", line 181, in _get_response
    response = wrapped_callback(request, *callback_args, **callback_kwargs)
  File "C:\ProgramData\Anaconda3\envs\tuPiM\lib\site-packages\django\views\generic\base.py", line 70, in view
    return self.dispatch(request, *args, **kwargs)
  File "C:\ProgramData\Anaconda3\envs\tuPiM\lib\site-packages\django\views\generic\base.py", line 98, in dispatch
    return handler(request, *args, **kwargs)
  File "C:\Users\Win10_Game_OS\PycharmProjects\sklad_site\Positions\views.py", line 64, in post
    positions = positions.exclude(quantity=0).exclude(quantity=None)
AttributeError: 'HttpResponse' object has no attribute 'exclude'
[2021-04-04 14:12:42,129] [INFO] => C:\Users\Win10_Game_OS\PycharmProjects\sklad_site\Positions\views.py changed, reloading.
[2021-04-04 14:16:36,309] [INFO] => Выбрано 5 позиций
[2021-04-04 14:17:19,233] [INFO] => Выбрано 2 позиций
[2021-04-04 14:36:23,080] [INFO] => Выбрано 7 позиций
[2021-04-04 14:36:31,286] [INFO] => Выбрано 5 позиций
[2021-04-04 14:36:34,322] [INFO] => Выбрано 21 позиций
[2021-04-04 14:36:40,270] [INFO] => По запросу <class 'str'> позиций не найдено
[2021-04-04 14:36:40,302] [ERROR] => Internal Server Error: /list/
Traceback (most recent call last):
  File "C:\ProgramData\Anaconda3\envs\tuPiM\lib\site-packages\django\core\handlers\exception.py", line 47, in inner
    response = get_response(request)
  File "C:\ProgramData\Anaconda3\envs\tuPiM\lib\site-packages\django\core\handlers\base.py", line 181, in _get_response
    response = wrapped_callback(request, *callback_args, **callback_kwargs)
  File "C:\ProgramData\Anaconda3\envs\tuPiM\lib\site-packages\django\views\generic\base.py", line 70, in view
    return self.dispatch(request, *args, **kwargs)
  File "C:\ProgramData\Anaconda3\envs\tuPiM\lib\site-packages\django\views\generic\base.py", line 98, in dispatch
    return handler(request, *args, **kwargs)
  File "C:\Users\Win10_Game_OS\PycharmProjects\sklad_site\Positions\views.py", line 63, in post
    positions = positions.exclude(quantity=0).exclude(quantity=None)
AttributeError: 'HttpResponse' object has no attribute 'exclude'
[2021-04-04 14:57:00,421] [INFO] => C:\Users\Win10_Game_OS\PycharmProjects\sklad_site\Positions\views.py changed, reloading.
[2021-04-04 15:00:16,293] [INFO] => Выбрано 4 позиций
[2021-04-04 15:05:10,301] [INFO] => Выбрано 17 позиций
[2021-04-04 15:05:17,686] [INFO] => Выбрано 5 позиций
[2021-04-04 15:05:24,664] [INFO] => Выбрано 7 позиций
[2021-04-04 15:05:58,135] [INFO] => Выбрано 5 позиций
[2021-04-04 15:06:12,030] [INFO] => Выбрано 11 позиций
[2021-04-04 15:06:47,606] [INFO] => Выбрано 20 позиций
[2021-04-04 17:45:00,455] [INFO] => C:\Users\Win10_Game_OS\PycharmProjects\sklad_site\Positions\views.py changed, reloading.
[2021-04-04 17:49:43,914] [ERROR] => Internal Server Error: /out/
Traceback (most recent call last):
  File "C:\ProgramData\Anaconda3\envs\tuPiM\lib\site-packages\django\db\models\fields\__init__.py", line 1774, in get_prep_value
    return int(value)
ValueError: invalid literal for int() with base 10: ''

The above exception was the direct cause of the following exception:

Traceback (most recent call last):
  File "C:\ProgramData\Anaconda3\envs\tuPiM\lib\site-packages\django\core\handlers\exception.py", line 47, in inner
    response = get_response(request)
  File "C:\ProgramData\Anaconda3\envs\tuPiM\lib\site-packages\django\core\handlers\base.py", line 181, in _get_response
    response = wrapped_callback(request, *callback_args, **callback_kwargs)
  File "C:\ProgramData\Anaconda3\envs\tuPiM\lib\site-packages\django\views\generic\base.py", line 70, in view
    return self.dispatch(request, *args, **kwargs)
  File "C:\ProgramData\Anaconda3\envs\tuPiM\lib\site-packages\django\views\generic\base.py", line 98, in dispatch
    return handler(request, *args, **kwargs)
  File "C:\Users\Win10_Game_OS\PycharmProjects\sklad_site\Positions\views.py", line 101, in get
    out_dict["positions"].append(Positions.objects.get(pk=request.GET.get("list")))
  File "C:\ProgramData\Anaconda3\envs\tuPiM\lib\site-packages\django\db\models\manager.py", line 85, in manager_method
    return getattr(self.get_queryset(), name)(*args, **kwargs)
  File "C:\ProgramData\Anaconda3\envs\tuPiM\lib\site-packages\django\db\models\query.py", line 418, in get
    clone = self._chain() if self.query.combinator else self.filter(*args, **kwargs)
  File "C:\ProgramData\Anaconda3\envs\tuPiM\lib\site-packages\django\db\models\query.py", line 942, in filter
    return self._filter_or_exclude(False, *args, **kwargs)
  File "C:\ProgramData\Anaconda3\envs\tuPiM\lib\site-packages\django\db\models\query.py", line 962, in _filter_or_exclude
    clone._filter_or_exclude_inplace(negate, *args, **kwargs)
  File "C:\ProgramData\Anaconda3\envs\tuPiM\lib\site-packages\django\db\models\query.py", line 969, in _filter_or_exclude_inplace
    self._query.add_q(Q(*args, **kwargs))
  File "C:\ProgramData\Anaconda3\envs\tuPiM\lib\site-packages\django\db\models\sql\query.py", line 1358, in add_q
    clause, _ = self._add_q(q_object, self.used_aliases)
  File "C:\ProgramData\Anaconda3\envs\tuPiM\lib\site-packages\django\db\models\sql\query.py", line 1380, in _add_q
    split_subq=split_subq, check_filterable=check_filterable,
  File "C:\ProgramData\Anaconda3\envs\tuPiM\lib\site-packages\django\db\models\sql\query.py", line 1319, in build_filter
    condition = self.build_lookup(lookups, col, value)
  File "C:\ProgramData\Anaconda3\envs\tuPiM\lib\site-packages\django\db\models\sql\query.py", line 1165, in build_lookup
    lookup = lookup_class(lhs, rhs)
  File "C:\ProgramData\Anaconda3\envs\tuPiM\lib\site-packages\django\db\models\lookups.py", line 24, in __init__
    self.rhs = self.get_prep_lookup()
  File "C:\ProgramData\Anaconda3\envs\tuPiM\lib\site-packages\django\db\models\lookups.py", line 76, in get_prep_lookup
    return self.lhs.output_field.get_prep_value(self.rhs)
  File "C:\ProgramData\Anaconda3\envs\tuPiM\lib\site-packages\django\db\models\fields\__init__.py", line 1778, in get_prep_value
    ) from e
ValueError: Field 'id' expected a number but got ''.
[2021-04-04 17:54:55,292] [INFO] => C:\Users\Win10_Game_OS\PycharmProjects\sklad_site\Positions\views.py changed, reloading.
[2021-04-04 17:55:09,915] [ERROR] => Internal Server Error: /out/
Traceback (most recent call last):
  File "C:\ProgramData\Anaconda3\envs\tuPiM\lib\site-packages\django\core\handlers\exception.py", line 47, in inner
    response = get_response(request)
  File "C:\ProgramData\Anaconda3\envs\tuPiM\lib\site-packages\django\core\handlers\base.py", line 181, in _get_response
    response = wrapped_callback(request, *callback_args, **callback_kwargs)
  File "C:\ProgramData\Anaconda3\envs\tuPiM\lib\site-packages\django\views\generic\base.py", line 70, in view
    return self.dispatch(request, *args, **kwargs)
  File "C:\ProgramData\Anaconda3\envs\tuPiM\lib\site-packages\django\views\generic\base.py", line 98, in dispatch
    return handler(request, *args, **kwargs)
  File "C:\Users\Win10_Game_OS\PycharmProjects\sklad_site\Positions\views.py", line 105, in get
    positions = find_pos(request.GET.get("reg_search")).exclude(quantity=None)
AttributeError: 'NoneType' object has no attribute 'exclude'
[2021-04-04 17:56:52,052] [INFO] => C:\Users\Win10_Game_OS\PycharmProjects\sklad_site\Positions\views.py changed, reloading.
[2021-04-04 17:57:12,539] [INFO] => Выбрано 229 позиций
[2021-04-04 17:57:39,941] [INFO] => C:\Users\Win10_Game_OS\PycharmProjects\sklad_site\Positions\views.py changed, reloading.
[2021-04-04 17:57:44,658] [INFO] => Выбрано 229 позиций
[2021-04-04 17:58:14,961] [INFO] => Выбрано 7 позиций
[2021-04-04 17:59:46,675] [INFO] => C:\Users\Win10_Game_OS\PycharmProjects\sklad_site\Positions\views.py changed, reloading.
[2021-04-04 17:59:50,224] [INFO] => Выбрано 7 позиций
[2021-04-04 18:02:49,225] [INFO] => C:\Users\Win10_Game_OS\PycharmProjects\sklad_site\Positions\views.py changed, reloading.
[2021-04-04 18:06:26,612] [INFO] => C:\Users\Win10_Game_OS\PycharmProjects\sklad_site\Positions\views.py changed, reloading.
[2021-04-04 18:07:05,857] [INFO] => C:\Users\Win10_Game_OS\PycharmProjects\sklad_site\Positions\views.py changed, reloading.
[2021-04-04 18:17:17,444] [INFO] => C:\Users\Win10_Game_OS\PycharmProjects\sklad_site\Positions\views.py changed, reloading.
[2021-04-04 18:17:34,118] [ERROR] => Internal Server Error: /out/
Traceback (most recent call last):
  File "C:\ProgramData\Anaconda3\envs\tuPiM\lib\site-packages\django\core\handlers\exception.py", line 47, in inner
    response = get_response(request)
  File "C:\ProgramData\Anaconda3\envs\tuPiM\lib\site-packages\django\core\handlers\base.py", line 181, in _get_response
    response = wrapped_callback(request, *callback_args, **callback_kwargs)
  File "C:\ProgramData\Anaconda3\envs\tuPiM\lib\site-packages\django\views\generic\base.py", line 70, in view
    return self.dispatch(request, *args, **kwargs)
  File "C:\ProgramData\Anaconda3\envs\tuPiM\lib\site-packages\django\views\generic\base.py", line 98, in dispatch
    return handler(request, *args, **kwargs)
  File "C:\Users\Win10_Game_OS\PycharmProjects\sklad_site\Positions\views.py", line 124, in post
    if _dict["otpr"] is not None:
KeyError: 'otpr'
[2021-04-04 18:19:23,568] [INFO] => C:\Users\Win10_Game_OS\PycharmProjects\sklad_site\Positions\views.py changed, reloading.
[2021-04-04 18:20:46,704] [INFO] => C:\Users\Win10_Game_OS\PycharmProjects\sklad_site\Positions\views.py changed, reloading.
[2021-04-04 18:21:18,847] [INFO] => C:\Users\Win10_Game_OS\PycharmProjects\sklad_site\Positions\views.py changed, reloading.
[2021-04-04 18:22:35,679] [INFO] => C:\Users\Win10_Game_OS\PycharmProjects\sklad_site\Positions\views.py changed, reloading.
[2021-04-04 18:27:28,520] [INFO] => C:\Users\Win10_Game_OS\PycharmProjects\sklad_site\Positions\views.py changed, reloading.
[2021-04-04 18:29:28,316] [INFO] => C:\Users\Win10_Game_OS\PycharmProjects\sklad_site\Positions\views.py changed, reloading.
[2021-04-04 18:30:05,715] [INFO] => C:\Users\Win10_Game_OS\PycharmProjects\sklad_site\Positions\views.py changed, reloading.
[2021-04-04 18:30:30,632] [WARNING] => Not Found: /out/127.0.0.1:8000/out/
[2021-04-04 18:31:02,261] [INFO] => C:\Users\Win10_Game_OS\PycharmProjects\sklad_site\Positions\views.py changed, reloading.
[2021-04-04 18:31:07,514] [WARNING] => Not Found: /out/127.0.0.1:8000
[2021-04-04 18:31:18,621] [INFO] => C:\Users\Win10_Game_OS\PycharmProjects\sklad_site\Positions\views.py changed, reloading.
[2021-04-04 18:38:45,459] [INFO] => C:\Users\Win10_Game_OS\PycharmProjects\sklad_site\Positions\views.py changed, reloading.
[2021-04-04 18:38:59,695] [WARNING] => Not Found: /out/127.0.0.1:8000
[2021-04-04 18:39:19,782] [INFO] => C:\Users\Win10_Game_OS\PycharmProjects\sklad_site\Positions\views.py changed, reloading.
[2021-04-04 18:41:08,328] [INFO] => C:\Users\Win10_Game_OS\PycharmProjects\sklad_site\Positions\views.py changed, reloading.
[2021-04-04 18:41:27,644] [WARNING] => Not Found: /out/document.location.host
[2021-04-04 18:41:58,247] [INFO] => C:\Users\Win10_Game_OS\PycharmProjects\sklad_site\Positions\views.py changed, reloading.
[2021-04-04 18:43:19,242] [INFO] => C:\Users\Win10_Game_OS\PycharmProjects\sklad_site\Positions\views.py changed, reloading.
[2021-04-04 18:44:08,592] [INFO] => C:\Users\Win10_Game_OS\PycharmProjects\sklad_site\Positions\views.py changed, reloading.
[2021-04-04 18:44:12,092] [WARNING] => Not Found: /out/documet.location.host
[2021-04-04 18:44:22,802] [INFO] => C:\Users\Win10_Game_OS\PycharmProjects\sklad_site\Positions\views.py changed, reloading.
[2021-04-04 18:44:27,497] [WARNING] => Not Found: /out/document.location.host
[2021-04-04 18:44:41,411] [INFO] => C:\Users\Win10_Game_OS\PycharmProjects\sklad_site\Positions\views.py changed, reloading.
[2021-04-04 18:44:47,401] [WARNING] => Not Found: /out/document.location.host
[2021-04-04 18:48:03,942] [INFO] => C:\Users\Win10_Game_OS\PycharmProjects\sklad_site\Positions\views.py changed, reloading.
[2021-04-04 18:49:01,364] [INFO] => C:\Users\Win10_Game_OS\PycharmProjects\sklad_site\Positions\views.py changed, reloading.
[2021-04-04 18:49:22,200] [INFO] => C:\Users\Win10_Game_OS\PycharmProjects\sklad_site\Positions\views.py changed, reloading.
[2021-04-04 18:49:39,482] [INFO] => C:\Users\Win10_Game_OS\PycharmProjects\sklad_site\Positions\views.py changed, reloading.
[2021-04-04 18:49:41,830] [ERROR] => Internal Server Error: /out/
Traceback (most recent call last):
  File "C:\ProgramData\Anaconda3\envs\tuPiM\lib\site-packages\django\core\handlers\exception.py", line 47, in inner
    response = get_response(request)
  File "C:\ProgramData\Anaconda3\envs\tuPiM\lib\site-packages\django\core\handlers\base.py", line 181, in _get_response
    response = wrapped_callback(request, *callback_args, **callback_kwargs)
  File "C:\ProgramData\Anaconda3\envs\tuPiM\lib\site-packages\django\views\generic\base.py", line 70, in view
    return self.dispatch(request, *args, **kwargs)
  File "C:\ProgramData\Anaconda3\envs\tuPiM\lib\site-packages\django\views\generic\base.py", line 98, in dispatch
    return handler(request, *args, **kwargs)
  File "C:\Users\Win10_Game_OS\PycharmProjects\sklad_site\Positions\views.py", line 135, in post
    print(dict(request))
ValueError: dictionary update sequence element #0 has length 117; 2 is required
[2021-04-04 18:50:01,057] [INFO] => C:\Users\Win10_Game_OS\PycharmProjects\sklad_site\Positions\views.py changed, reloading.
[2021-04-04 18:50:03,521] [ERROR] => Internal Server Error: /out/
Traceback (most recent call last):
  File "C:\ProgramData\Anaconda3\envs\tuPiM\lib\site-packages\django\core\handlers\exception.py", line 47, in inner
    response = get_response(request)
  File "C:\ProgramData\Anaconda3\envs\tuPiM\lib\site-packages\django\core\handlers\base.py", line 181, in _get_response
    response = wrapped_callback(request, *callback_args, **callback_kwargs)
  File "C:\ProgramData\Anaconda3\envs\tuPiM\lib\site-packages\django\views\generic\base.py", line 70, in view
    return self.dispatch(request, *args, **kwargs)
  File "C:\ProgramData\Anaconda3\envs\tuPiM\lib\site-packages\django\views\generic\base.py", line 98, in dispatch
    return handler(request, *args, **kwargs)
  File "C:\Users\Win10_Game_OS\PycharmProjects\sklad_site\Positions\views.py", line 135, in post
    print(request.dict)
AttributeError: 'WSGIRequest' object has no attribute 'dict'
[2021-04-04 18:50:13,269] [INFO] => C:\Users\Win10_Game_OS\PycharmProjects\sklad_site\Positions\views.py changed, reloading.
[2021-04-04 18:53:09,470] [INFO] => C:\Users\Win10_Game_OS\PycharmProjects\sklad_site\Positions\views.py changed, reloading.
[2021-04-04 18:53:13,831] [ERROR] => Internal Server Error: /out/
Traceback (most recent call last):
  File "C:\ProgramData\Anaconda3\envs\tuPiM\lib\site-packages\django\core\handlers\exception.py", line 47, in inner
    response = get_response(request)
  File "C:\ProgramData\Anaconda3\envs\tuPiM\lib\site-packages\django\core\handlers\base.py", line 181, in _get_response
    response = wrapped_callback(request, *callback_args, **callback_kwargs)
  File "C:\ProgramData\Anaconda3\envs\tuPiM\lib\site-packages\django\views\generic\base.py", line 70, in view
    return self.dispatch(request, *args, **kwargs)
  File "C:\ProgramData\Anaconda3\envs\tuPiM\lib\site-packages\django\views\generic\base.py", line 98, in dispatch
    return handler(request, *args, **kwargs)
  File "C:\Users\Win10_Game_OS\PycharmProjects\sklad_site\Positions\views.py", line 135, in post
    print(request.HTTP_ORIGIN)
AttributeError: 'WSGIRequest' object has no attribute 'HTTP_ORIGIN'
[2021-04-04 18:54:01,290] [INFO] => C:\Users\Win10_Game_OS\PycharmProjects\sklad_site\Positions\views.py changed, reloading.
[2021-04-04 18:54:04,137] [ERROR] => Internal Server Error: /out/
Traceback (most recent call last):
  File "C:\ProgramData\Anaconda3\envs\tuPiM\lib\site-packages\django\core\handlers\exception.py", line 47, in inner
    response = get_response(request)
  File "C:\ProgramData\Anaconda3\envs\tuPiM\lib\site-packages\django\core\handlers\base.py", line 181, in _get_response
    response = wrapped_callback(request, *callback_args, **callback_kwargs)
  File "C:\ProgramData\Anaconda3\envs\tuPiM\lib\site-packages\django\views\generic\base.py", line 70, in view
    return self.dispatch(request, *args, **kwargs)
  File "C:\ProgramData\Anaconda3\envs\tuPiM\lib\site-packages\django\views\generic\base.py", line 98, in dispatch
    return handler(request, *args, **kwargs)
  File "C:\Users\Win10_Game_OS\PycharmProjects\sklad_site\Positions\views.py", line 135, in post
    print(request.environ.HTTP_ORIGIN)
AttributeError: 'dict' object has no attribute 'HTTP_ORIGIN'
[2021-04-04 18:54:20,209] [INFO] => C:\Users\Win10_Game_OS\PycharmProjects\sklad_site\Positions\views.py changed, reloading.
[2021-04-04 18:54:45,857] [INFO] => C:\Users\Win10_Game_OS\PycharmProjects\sklad_site\Positions\views.py changed, reloading.
[2021-04-04 18:55:45,247] [INFO] => C:\Users\Win10_Game_OS\PycharmProjects\sklad_site\Positions\views.py changed, reloading.
[2021-04-04 19:05:25,008] [INFO] => C:\Users\Win10_Game_OS\PycharmProjects\sklad_site\Positions\views.py changed, reloading.
[2021-04-04 19:06:39,792] [INFO] => C:\Users\Win10_Game_OS\PycharmProjects\sklad_site\Positions\views.py changed, reloading.
[2021-04-04 19:06:58,518] [INFO] => C:\Users\Win10_Game_OS\PycharmProjects\sklad_site\Positions\views.py changed, reloading.
[2021-04-04 19:16:02,716] [INFO] => C:\Users\Win10_Game_OS\PycharmProjects\sklad_site\Positions\views.py changed, reloading.
[2021-04-04 19:18:49,013] [INFO] => C:\Users\Win10_Game_OS\PycharmProjects\sklad_site\Positions\views.py changed, reloading.
[2021-04-04 19:18:51,596] [ERROR] => Internal Server Error: /out/
Traceback (most recent call last):
  File "C:\ProgramData\Anaconda3\envs\tuPiM\lib\site-packages\django\core\handlers\exception.py", line 47, in inner
    response = get_response(request)
  File "C:\ProgramData\Anaconda3\envs\tuPiM\lib\site-packages\django\core\handlers\base.py", line 181, in _get_response
    response = wrapped_callback(request, *callback_args, **callback_kwargs)
  File "C:\ProgramData\Anaconda3\envs\tuPiM\lib\site-packages\django\views\generic\base.py", line 70, in view
    return self.dispatch(request, *args, **kwargs)
  File "C:\ProgramData\Anaconda3\envs\tuPiM\lib\site-packages\django\views\generic\base.py", line 98, in dispatch
    return handler(request, *args, **kwargs)
  File "C:\Users\Win10_Game_OS\PycharmProjects\sklad_site\Positions\views.py", line 142, in post
    "mol": out_dict["mol"].name,
KeyError: 'mol'
[2021-04-04 19:19:00,068] [ERROR] => Internal Server Error: /out/
Traceback (most recent call last):
  File "C:\ProgramData\Anaconda3\envs\tuPiM\lib\site-packages\django\core\handlers\exception.py", line 47, in inner
    response = get_response(request)
  File "C:\ProgramData\Anaconda3\envs\tuPiM\lib\site-packages\django\core\handlers\base.py", line 181, in _get_response
    response = wrapped_callback(request, *callback_args, **callback_kwargs)
  File "C:\ProgramData\Anaconda3\envs\tuPiM\lib\site-packages\django\views\generic\base.py", line 70, in view
    return self.dispatch(request, *args, **kwargs)
  File "C:\ProgramData\Anaconda3\envs\tuPiM\lib\site-packages\django\views\generic\base.py", line 98, in dispatch
    return handler(request, *args, **kwargs)
  File "C:\Users\Win10_Game_OS\PycharmProjects\sklad_site\Positions\views.py", line 142, in post
    "mol": out_dict["mol"].name,
KeyError: 'mol'
[2021-04-04 19:19:32,212] [ERROR] => Internal Server Error: /out/
Traceback (most recent call last):
  File "C:\ProgramData\Anaconda3\envs\tuPiM\lib\site-packages\django\core\handlers\exception.py", line 47, in inner
    response = get_response(request)
  File "C:\ProgramData\Anaconda3\envs\tuPiM\lib\site-packages\django\core\handlers\base.py", line 181, in _get_response
    response = wrapped_callback(request, *callback_args, **callback_kwargs)
  File "C:\ProgramData\Anaconda3\envs\tuPiM\lib\site-packages\django\views\generic\base.py", line 70, in view
    return self.dispatch(request, *args, **kwargs)
  File "C:\ProgramData\Anaconda3\envs\tuPiM\lib\site-packages\django\views\generic\base.py", line 98, in dispatch
    return handler(request, *args, **kwargs)
  File "C:\Users\Win10_Game_OS\PycharmProjects\sklad_site\Positions\views.py", line 142, in post
    "mol": out_dict["mol"].name,
KeyError: 'mol'
[2021-04-04 19:23:17,635] [INFO] => C:\Users\Win10_Game_OS\PycharmProjects\sklad_site\Positions\views.py changed, reloading.
[2021-04-04 19:43:14,430] [INFO] => C:\Users\Win10_Game_OS\PycharmProjects\sklad_site\Positions\func_for_excel.py changed, reloading.
[2021-04-04 19:43:31,181] [ERROR] => Internal Server Error: /out/
Traceback (most recent call last):
  File "C:\ProgramData\Anaconda3\envs\tuPiM\lib\site-packages\django\core\handlers\exception.py", line 47, in inner
    response = get_response(request)
  File "C:\ProgramData\Anaconda3\envs\tuPiM\lib\site-packages\django\core\handlers\base.py", line 181, in _get_response
    response = wrapped_callback(request, *callback_args, **callback_kwargs)
  File "C:\ProgramData\Anaconda3\envs\tuPiM\lib\site-packages\django\views\generic\base.py", line 70, in view
    return self.dispatch(request, *args, **kwargs)
  File "C:\ProgramData\Anaconda3\envs\tuPiM\lib\site-packages\django\views\generic\base.py", line 98, in dispatch
    return handler(request, *args, **kwargs)
  File "C:\Users\Win10_Game_OS\PycharmProjects\sklad_site\Positions\views.py", line 134, in post
    print(_dict)
TypeError: print() takes 0 positional arguments but 1 was given
[2021-04-04 19:44:04,829] [INFO] => C:\Users\Win10_Game_OS\PycharmProjects\sklad_site\Positions\func_for_excel.py changed, reloading.
[2021-04-04 19:44:41,680] [INFO] => Выбрано 1 позиций
[2021-04-04 19:44:53,711] [ERROR] => Internal Server Error: /out/
Traceback (most recent call last):
  File "C:\ProgramData\Anaconda3\envs\tuPiM\lib\site-packages\django\core\handlers\exception.py", line 47, in inner
    response = get_response(request)
  File "C:\ProgramData\Anaconda3\envs\tuPiM\lib\site-packages\django\core\handlers\base.py", line 181, in _get_response
    response = wrapped_callback(request, *callback_args, **callback_kwargs)
  File "C:\ProgramData\Anaconda3\envs\tuPiM\lib\site-packages\django\views\generic\base.py", line 70, in view
    return self.dispatch(request, *args, **kwargs)
  File "C:\ProgramData\Anaconda3\envs\tuPiM\lib\site-packages\django\views\generic\base.py", line 98, in dispatch
    return handler(request, *args, **kwargs)
  File "C:\Users\Win10_Game_OS\PycharmProjects\sklad_site\Positions\views.py", line 154, in post
    write_to_excel(_data)
  File "C:\Users\Win10_Game_OS\PycharmProjects\sklad_site\Positions\func_for_excel.py", line 66, in write_to_excel
    wb = openpyxl.load_workbook(path)
  File "C:\ProgramData\Anaconda3\envs\tuPiM\lib\site-packages\openpyxl\reader\excel.py", line 316, in load_workbook
    data_only, keep_links)
  File "C:\ProgramData\Anaconda3\envs\tuPiM\lib\site-packages\openpyxl\reader\excel.py", line 124, in __init__
    self.archive = _validate_archive(fn)
  File "C:\ProgramData\Anaconda3\envs\tuPiM\lib\site-packages\openpyxl\reader\excel.py", line 96, in _validate_archive
    archive = ZipFile(filename, 'r')
  File "C:\ProgramData\Anaconda3\envs\tuPiM\lib\zipfile.py", line 1240, in __init__
    self.fp = io.open(file, filemode)
FileNotFoundError: [Errno 2] No such file or directory: 'prin-template.xlsx'
[2021-04-04 19:48:54,256] [INFO] => C:\Users\Win10_Game_OS\PycharmProjects\sklad_site\Positions\func_for_excel.py changed, reloading.
[2021-04-04 19:48:58,019] [ERROR] => Internal Server Error: /out/
Traceback (most recent call last):
  File "C:\ProgramData\Anaconda3\envs\tuPiM\lib\site-packages\django\core\handlers\exception.py", line 47, in inner
    response = get_response(request)
  File "C:\ProgramData\Anaconda3\envs\tuPiM\lib\site-packages\django\core\handlers\base.py", line 181, in _get_response
    response = wrapped_callback(request, *callback_args, **callback_kwargs)
  File "C:\ProgramData\Anaconda3\envs\tuPiM\lib\site-packages\django\views\generic\base.py", line 70, in view
    return self.dispatch(request, *args, **kwargs)
  File "C:\ProgramData\Anaconda3\envs\tuPiM\lib\site-packages\django\views\generic\base.py", line 98, in dispatch
    return handler(request, *args, **kwargs)
  File "C:\Users\Win10_Game_OS\PycharmProjects\sklad_site\Positions\views.py", line 143, in post
    "mol": out_dict["mol"].name,
KeyError: 'mol'
[2021-04-04 19:49:15,576] [ERROR] => Internal Server Error: /out/
Traceback (most recent call last):
  File "C:\ProgramData\Anaconda3\envs\tuPiM\lib\site-packages\django\core\handlers\exception.py", line 47, in inner
    response = get_response(request)
  File "C:\ProgramData\Anaconda3\envs\tuPiM\lib\site-packages\django\core\handlers\base.py", line 181, in _get_response
    response = wrapped_callback(request, *callback_args, **callback_kwargs)
  File "C:\ProgramData\Anaconda3\envs\tuPiM\lib\site-packages\django\views\generic\base.py", line 70, in view
    return self.dispatch(request, *args, **kwargs)
  File "C:\ProgramData\Anaconda3\envs\tuPiM\lib\site-packages\django\views\generic\base.py", line 98, in dispatch
    return handler(request, *args, **kwargs)
  File "C:\Users\Win10_Game_OS\PycharmProjects\sklad_site\Positions\views.py", line 154, in post
    write_to_excel(_data)
  File "C:\Users\Win10_Game_OS\PycharmProjects\sklad_site\Positions\func_for_excel.py", line 67, in write_to_excel
    wb = openpyxl.load_workbook(path)
  File "C:\ProgramData\Anaconda3\envs\tuPiM\lib\site-packages\openpyxl\reader\excel.py", line 316, in load_workbook
    data_only, keep_links)
  File "C:\ProgramData\Anaconda3\envs\tuPiM\lib\site-packages\openpyxl\reader\excel.py", line 124, in __init__
    self.archive = _validate_archive(fn)
  File "C:\ProgramData\Anaconda3\envs\tuPiM\lib\site-packages\openpyxl\reader\excel.py", line 96, in _validate_archive
    archive = ZipFile(filename, 'r')
  File "C:\ProgramData\Anaconda3\envs\tuPiM\lib\zipfile.py", line 1240, in __init__
    self.fp = io.open(file, filemode)
FileNotFoundError: [Errno 2] No such file or directory: 'prin-template.xlsx'
[2021-04-04 19:49:54,343] [INFO] => C:\Users\Win10_Game_OS\PycharmProjects\sklad_site\Positions\func_for_excel.py changed, reloading.
[2021-04-04 19:50:05,127] [ERROR] => Internal Server Error: /out/
Traceback (most recent call last):
  File "C:\ProgramData\Anaconda3\envs\tuPiM\lib\site-packages\django\core\handlers\exception.py", line 47, in inner
    response = get_response(request)
  File "C:\ProgramData\Anaconda3\envs\tuPiM\lib\site-packages\django\core\handlers\base.py", line 181, in _get_response
    response = wrapped_callback(request, *callback_args, **callback_kwargs)
  File "C:\ProgramData\Anaconda3\envs\tuPiM\lib\site-packages\django\views\generic\base.py", line 70, in view
    return self.dispatch(request, *args, **kwargs)
  File "C:\ProgramData\Anaconda3\envs\tuPiM\lib\site-packages\django\views\generic\base.py", line 98, in dispatch
    return handler(request, *args, **kwargs)
  File "C:\Users\Win10_Game_OS\PycharmProjects\sklad_site\Positions\views.py", line 154, in post
    write_to_excel(_data)
  File "C:\Users\Win10_Game_OS\PycharmProjects\sklad_site\Positions\func_for_excel.py", line 67, in write_to_excel
    wb = openpyxl.load_workbook(path)
  File "C:\ProgramData\Anaconda3\envs\tuPiM\lib\site-packages\openpyxl\reader\excel.py", line 316, in load_workbook
    data_only, keep_links)
  File "C:\ProgramData\Anaconda3\envs\tuPiM\lib\site-packages\openpyxl\reader\excel.py", line 124, in __init__
    self.archive = _validate_archive(fn)
  File "C:\ProgramData\Anaconda3\envs\tuPiM\lib\site-packages\openpyxl\reader\excel.py", line 96, in _validate_archive
    archive = ZipFile(filename, 'r')
  File "C:\ProgramData\Anaconda3\envs\tuPiM\lib\zipfile.py", line 1240, in __init__
    self.fp = io.open(file, filemode)
FileNotFoundError: [Errno 2] No such file or directory: 'C:\\Users\\Win10_Game_OS\\PycharmProjects\\sklad_siteprin-template.xlsx'
[2021-04-04 19:50:43,017] [INFO] => C:\Users\Win10_Game_OS\PycharmProjects\sklad_site\Positions\func_for_excel.py changed, reloading.
[2021-04-04 19:50:56,604] [ERROR] => Internal Server Error: /out/
Traceback (most recent call last):
  File "C:\ProgramData\Anaconda3\envs\tuPiM\lib\site-packages\django\core\handlers\exception.py", line 47, in inner
    response = get_response(request)
  File "C:\ProgramData\Anaconda3\envs\tuPiM\lib\site-packages\django\core\handlers\base.py", line 181, in _get_response
    response = wrapped_callback(request, *callback_args, **callback_kwargs)
  File "C:\ProgramData\Anaconda3\envs\tuPiM\lib\site-packages\django\views\generic\base.py", line 70, in view
    return self.dispatch(request, *args, **kwargs)
  File "C:\ProgramData\Anaconda3\envs\tuPiM\lib\site-packages\django\views\generic\base.py", line 98, in dispatch
    return handler(request, *args, **kwargs)
  File "C:\Users\Win10_Game_OS\PycharmProjects\sklad_site\Positions\views.py", line 154, in post
    write_to_excel(_data)
  File "C:\Users\Win10_Game_OS\PycharmProjects\sklad_site\Positions\func_for_excel.py", line 67, in write_to_excel
    wb = openpyxl.load_workbook(path)
  File "C:\ProgramData\Anaconda3\envs\tuPiM\lib\site-packages\openpyxl\reader\excel.py", line 316, in load_workbook
    data_only, keep_links)
  File "C:\ProgramData\Anaconda3\envs\tuPiM\lib\site-packages\openpyxl\reader\excel.py", line 124, in __init__
    self.archive = _validate_archive(fn)
  File "C:\ProgramData\Anaconda3\envs\tuPiM\lib\site-packages\openpyxl\reader\excel.py", line 96, in _validate_archive
    archive = ZipFile(filename, 'r')
  File "C:\ProgramData\Anaconda3\envs\tuPiM\lib\zipfile.py", line 1240, in __init__
    self.fp = io.open(file, filemode)
FileNotFoundError: [Errno 2] No such file or directory: 'C:\\Users\\Win10_Game_OS\\PycharmProjects\\sklad_site\\prin-template.xlsx'
[2021-04-04 19:52:29,034] [INFO] => C:\Users\Win10_Game_OS\PycharmProjects\sklad_site\Positions\func_for_excel.py changed, reloading.
[2021-04-04 19:56:16,296] [INFO] => C:\Users\Win10_Game_OS\PycharmProjects\sklad_site\Positions\views.py changed, reloading.
[2021-04-04 19:58:00,705] [INFO] => C:\Users\Win10_Game_OS\PycharmProjects\sklad_site\Positions\views.py changed, reloading.
[2021-04-04 20:00:58,950] [INFO] => C:\Users\Win10_Game_OS\PycharmProjects\sklad_site\Positions\func_for_excel.py changed, reloading.
[2021-04-04 20:01:09,393] [INFO] => C:\Users\Win10_Game_OS\PycharmProjects\sklad_site\Positions\func_for_excel.py changed, reloading.
[2021-04-04 20:04:16,822] [INFO] => C:\Users\Win10_Game_OS\PycharmProjects\sklad_site\Positions\views.py changed, reloading.
[2021-04-04 20:04:34,657] [ERROR] => Internal Server Error: /out/
Traceback (most recent call last):
  File "C:\ProgramData\Anaconda3\envs\tuPiM\lib\site-packages\django\core\handlers\exception.py", line 47, in inner
    response = get_response(request)
  File "C:\ProgramData\Anaconda3\envs\tuPiM\lib\site-packages\django\core\handlers\base.py", line 181, in _get_response
    response = wrapped_callback(request, *callback_args, **callback_kwargs)
  File "C:\ProgramData\Anaconda3\envs\tuPiM\lib\site-packages\django\views\generic\base.py", line 70, in view
    return self.dispatch(request, *args, **kwargs)
  File "C:\ProgramData\Anaconda3\envs\tuPiM\lib\site-packages\django\views\generic\base.py", line 98, in dispatch
    return handler(request, *args, **kwargs)
  File "C:\Users\Win10_Game_OS\PycharmProjects\sklad_site\Positions\views.py", line 156, in post
    CoInitializeEx(None, COINIT_MULTITHREADED)
TypeError: CoInitializeEx() takes exactly 1 argument (2 given)
[2021-04-04 20:05:32,281] [INFO] => C:\Users\Win10_Game_OS\PycharmProjects\sklad_site\Positions\views.py changed, reloading.
[2021-04-04 20:05:47,681] [ERROR] => Internal Server Error: /out/
Traceback (most recent call last):
  File "C:\ProgramData\Anaconda3\envs\tuPiM\lib\site-packages\django\core\handlers\exception.py", line 47, in inner
    response = get_response(request)
  File "C:\ProgramData\Anaconda3\envs\tuPiM\lib\site-packages\django\core\handlers\base.py", line 181, in _get_response
    response = wrapped_callback(request, *callback_args, **callback_kwargs)
  File "C:\ProgramData\Anaconda3\envs\tuPiM\lib\site-packages\django\views\generic\base.py", line 70, in view
    return self.dispatch(request, *args, **kwargs)
  File "C:\ProgramData\Anaconda3\envs\tuPiM\lib\site-packages\django\views\generic\base.py", line 98, in dispatch
    return handler(request, *args, **kwargs)
  File "C:\Users\Win10_Game_OS\PycharmProjects\sklad_site\Positions\views.py", line 156, in post
    CoInitializeEx([None, COINIT_MULTITHREADED])
TypeError: an integer is required (got type list)
[2021-04-04 20:06:20,737] [INFO] => C:\Users\Win10_Game_OS\PycharmProjects\sklad_site\Positions\views.py changed, reloading.
[2021-04-04 20:06:31,328] [INFO] => C:\Users\Win10_Game_OS\PycharmProjects\sklad_site\Positions\views.py changed, reloading.
[2021-04-04 20:06:40,225] [ERROR] => Internal Server Error: /out/
Traceback (most recent call last):
  File "C:\ProgramData\Anaconda3\envs\tuPiM\lib\site-packages\django\core\handlers\exception.py", line 47, in inner
    response = get_response(request)
  File "C:\ProgramData\Anaconda3\envs\tuPiM\lib\site-packages\django\core\handlers\base.py", line 181, in _get_response
    response = wrapped_callback(request, *callback_args, **callback_kwargs)
  File "C:\ProgramData\Anaconda3\envs\tuPiM\lib\site-packages\django\views\generic\base.py", line 70, in view
    return self.dispatch(request, *args, **kwargs)
  File "C:\ProgramData\Anaconda3\envs\tuPiM\lib\site-packages\django\views\generic\base.py", line 98, in dispatch
    return handler(request, *args, **kwargs)
  File "C:\Users\Win10_Game_OS\PycharmProjects\sklad_site\Positions\views.py", line 156, in post
    CoInitializeEx(None)
TypeError: an integer is required (got type NoneType)
[2021-04-04 20:07:13,285] [INFO] => C:\Users\Win10_Game_OS\PycharmProjects\sklad_site\Positions\views.py changed, reloading.
[2021-04-04 20:08:07,816] [INFO] => C:\Users\Win10_Game_OS\PycharmProjects\sklad_site\Positions\views.py changed, reloading.
[2021-04-04 20:11:01,662] [INFO] => Выбрано 5 позиций
[2021-04-04 20:11:19,262] [INFO] => Выбрано 7 позиций
[2021-04-04 20:11:28,126] [INFO] => Выбрано 3 позиций
[2021-04-04 20:18:27,187] [INFO] => C:\Users\Win10_Game_OS\PycharmProjects\sklad_site\Positions\func_for_excel.py changed, reloading.
[2021-04-04 20:22:36,830] [INFO] => C:\Users\Win10_Game_OS\PycharmProjects\sklad_site\Positions\func_for_excel.py changed, reloading.
[2021-04-04 20:23:58,851] [INFO] => C:\Users\Win10_Game_OS\PycharmProjects\sklad_site\Positions\func_for_excel.py changed, reloading.
[2021-04-04 20:59:53,009] [INFO] => C:\Users\Win10_Game_OS\PycharmProjects\sklad_site\Positions\func_for_excel.py changed, reloading.
[2021-04-04 21:01:19,781] [INFO] => C:\Users\Win10_Game_OS\PycharmProjects\sklad_site\Positions\views.py changed, reloading.
[2021-04-04 21:08:40,711] [INFO] => C:\Users\Win10_Game_OS\PycharmProjects\sklad_site\Positions\views.py changed, reloading.
[2021-04-04 21:11:13,589] [INFO] => C:\Users\Win10_Game_OS\PycharmProjects\sklad_site\Positions\views.py changed, reloading.
[2021-04-04 21:13:00,450] [INFO] => C:\Users\Win10_Game_OS\PycharmProjects\sklad_site\Positions\views.py changed, reloading.
[2021-04-04 21:15:29,128] [INFO] => C:\Users\Win10_Game_OS\PycharmProjects\sklad_site\Positions\views.py changed, reloading.
[2021-04-04 21:15:58,671] [WARNING] => Not Found: /out/C:/Users/Win10_Game_OS/PycharmProjects/sklad_site/1.pdf
[2021-04-04 21:17:43,574] [INFO] => C:\Users\Win10_Game_OS\PycharmProjects\sklad_site\Positions\views.py changed, reloading.
[2021-04-04 21:17:50,363] [ERROR] => Internal Server Error: /out/
Traceback (most recent call last):
  File "C:\ProgramData\Anaconda3\envs\tuPiM\lib\site-packages\django\core\handlers\exception.py", line 47, in inner
    response = get_response(request)
  File "C:\ProgramData\Anaconda3\envs\tuPiM\lib\site-packages\django\core\handlers\base.py", line 181, in _get_response
    response = wrapped_callback(request, *callback_args, **callback_kwargs)
  File "C:\ProgramData\Anaconda3\envs\tuPiM\lib\site-packages\django\views\generic\base.py", line 70, in view
    return self.dispatch(request, *args, **kwargs)
  File "C:\ProgramData\Anaconda3\envs\tuPiM\lib\site-packages\django\views\generic\base.py", line 98, in dispatch
    return handler(request, *args, **kwargs)
  File "C:\Users\Win10_Game_OS\PycharmProjects\sklad_site\Positions\views.py", line 162, in post
    "mol": out_dict["mol"].name,
KeyError: 'mol'
[2021-04-04 21:20:10,195] [INFO] => C:\Users\Win10_Game_OS\PycharmProjects\sklad_site\Positions\views.py changed, reloading.
[2021-04-04 21:21:53,836] [INFO] => C:\Users\Win10_Game_OS\PycharmProjects\sklad_site\Positions\views.py changed, reloading.
[2021-04-04 21:25:11,038] [INFO] => C:\Users\Win10_Game_OS\PycharmProjects\sklad_site\Positions\views.py changed, reloading.
[2021-04-04 21:25:23,880] [INFO] => C:\Users\Win10_Game_OS\PycharmProjects\sklad_site\Positions\views.py changed, reloading.
[2021-04-04 21:25:45,203] [WARNING] => Not Found: /out/1.pdf
[2021-04-04 21:25:49,185] [WARNING] => Not Found: /out/1.pdf
[2021-04-04 21:26:11,466] [WARNING] => Not Found: /out/1.pdf
[2021-04-04 21:29:03,811] [WARNING] => Not Found: /out/1.pdf
[2021-04-04 21:29:07,803] [WARNING] => Not Found: /out/1.pdf
[2021-04-04 21:30:03,766] [INFO] => C:\Users\Win10_Game_OS\PycharmProjects\sklad_site\Positions\views.py changed, reloading.
[2021-04-04 21:32:14,395] [INFO] => C:\Users\Win10_Game_OS\PycharmProjects\sklad_site\Positions\views.py changed, reloading.
[2021-04-04 21:32:53,573] [INFO] => C:\Users\Win10_Game_OS\PycharmProjects\sklad_site\Positions\views.py changed, reloading.
[2021-04-05 20:35:31,584] [WARNING] => Not Found: /favicon.ico
[2021-04-06 16:24:25,632] [WARNING] => Not Found: /favicon.ico
[2021-04-06 16:24:41,094] [WARNING] => Not Found: /favicon.ico
[2021-04-06 22:53:36,526] [WARNING] => Not Found: /favicon.ico
[2021-04-07 11:38:09,925] [WARNING] => Not Found: /favicon.ico
[2021-04-07 11:39:30,597] [INFO] => Выбрано 1 позиций
[2021-04-07 11:39:47,437] [ERROR] => Internal Server Error: /out/
Traceback (most recent call last):
  File "C:\ProgramData\Anaconda3\envs\tuPiM\lib\site-packages\django\core\handlers\exception.py", line 47, in inner
    response = get_response(request)
  File "C:\ProgramData\Anaconda3\envs\tuPiM\lib\site-packages\django\core\handlers\base.py", line 181, in _get_response
    response = wrapped_callback(request, *callback_args, **callback_kwargs)
  File "C:\ProgramData\Anaconda3\envs\tuPiM\lib\site-packages\django\views\generic\base.py", line 70, in view
    return self.dispatch(request, *args, **kwargs)
  File "C:\ProgramData\Anaconda3\envs\tuPiM\lib\site-packages\django\views\generic\base.py", line 98, in dispatch
    return handler(request, *args, **kwargs)
  File "C:\Users\Win10_Game_OS\PycharmProjects\sklad_site\Positions\views.py", line 162, in post
    "mol": out_dict["mol"].name,
AttributeError: 'NoneType' object has no attribute 'name'
[2021-04-07 11:40:03,466] [ERROR] => Internal Server Error: /out/
Traceback (most recent call last):
  File "C:\ProgramData\Anaconda3\envs\tuPiM\lib\site-packages\django\core\handlers\exception.py", line 47, in inner
    response = get_response(request)
  File "C:\ProgramData\Anaconda3\envs\tuPiM\lib\site-packages\django\core\handlers\base.py", line 181, in _get_response
    response = wrapped_callback(request, *callback_args, **callback_kwargs)
  File "C:\ProgramData\Anaconda3\envs\tuPiM\lib\site-packages\django\views\generic\base.py", line 70, in view
    return self.dispatch(request, *args, **kwargs)
  File "C:\ProgramData\Anaconda3\envs\tuPiM\lib\site-packages\django\views\generic\base.py", line 98, in dispatch
    return handler(request, *args, **kwargs)
  File "C:\Users\Win10_Game_OS\PycharmProjects\sklad_site\Positions\views.py", line 162, in post
    "mol": out_dict["mol"].name,
AttributeError: 'NoneType' object has no attribute 'name'
[2021-04-07 11:40:23,284] [WARNING] => Not Found: /favicon.ico
[2021-04-07 12:11:34,506] [ERROR] => Internal Server Error: /out/
Traceback (most recent call last):
  File "C:\ProgramData\Anaconda3\envs\tuPiM\lib\site-packages\django\core\handlers\exception.py", line 47, in inner
    response = get_response(request)
  File "C:\ProgramData\Anaconda3\envs\tuPiM\lib\site-packages\django\core\handlers\base.py", line 181, in _get_response
    response = wrapped_callback(request, *callback_args, **callback_kwargs)
  File "C:\ProgramData\Anaconda3\envs\tuPiM\lib\site-packages\django\views\generic\base.py", line 70, in view
    return self.dispatch(request, *args, **kwargs)
  File "C:\ProgramData\Anaconda3\envs\tuPiM\lib\site-packages\django\views\generic\base.py", line 98, in dispatch
    return handler(request, *args, **kwargs)
  File "C:\Users\Win10_Game_OS\PycharmProjects\sklad_site\Positions\views.py", line 162, in post
    "mol": out_dict["mol"].name,
AttributeError: 'NoneType' object has no attribute 'name'
[2021-04-07 12:12:15,662] [INFO] => Выбрано 1 позиций
[2021-04-07 12:12:26,276] [INFO] => Выбрано 4 позиций
[2021-04-08 00:43:27,809] [WARNING] => Not Found: /favicon.ico
[2021-04-08 01:08:01,009] [WARNING] => Not Found: /favicon.ico
[2021-04-08 01:43:22,784] [ERROR] => Internal Server Error: /out/
Traceback (most recent call last):
  File "C:\ProgramData\Anaconda3\envs\tuPiM\lib\site-packages\django\core\handlers\exception.py", line 47, in inner
    response = get_response(request)
  File "C:\ProgramData\Anaconda3\envs\tuPiM\lib\site-packages\django\core\handlers\base.py", line 181, in _get_response
    response = wrapped_callback(request, *callback_args, **callback_kwargs)
  File "C:\ProgramData\Anaconda3\envs\tuPiM\lib\site-packages\django\views\generic\base.py", line 70, in view
    return self.dispatch(request, *args, **kwargs)
  File "C:\ProgramData\Anaconda3\envs\tuPiM\lib\site-packages\django\views\generic\base.py", line 98, in dispatch
    return handler(request, *args, **kwargs)
  File "C:\Users\Win10_Game_OS\PycharmProjects\sklad_site\Positions\views.py", line 162, in post
    "mol": out_dict["mol"].name,
AttributeError: 'NoneType' object has no attribute 'name'
[2021-04-08 01:43:34,166] [ERROR] => Internal Server Error: /out/
Traceback (most recent call last):
  File "C:\ProgramData\Anaconda3\envs\tuPiM\lib\site-packages\django\core\handlers\exception.py", line 47, in inner
    response = get_response(request)
  File "C:\ProgramData\Anaconda3\envs\tuPiM\lib\site-packages\django\core\handlers\base.py", line 181, in _get_response
    response = wrapped_callback(request, *callback_args, **callback_kwargs)
  File "C:\ProgramData\Anaconda3\envs\tuPiM\lib\site-packages\django\views\generic\base.py", line 70, in view
    return self.dispatch(request, *args, **kwargs)
  File "C:\ProgramData\Anaconda3\envs\tuPiM\lib\site-packages\django\views\generic\base.py", line 98, in dispatch
    return handler(request, *args, **kwargs)
  File "C:\Users\Win10_Game_OS\PycharmProjects\sklad_site\Positions\views.py", line 162, in post
    "mol": out_dict["mol"].name,
AttributeError: 'NoneType' object has no attribute 'name'
[2021-04-17 21:27:13,522] [WARNING] => Not Found: /favicon.ico
[2021-04-17 21:41:51,660] [INFO] => Выбрано 1 позиций
[2021-04-17 21:41:57,118] [INFO] => Выбрано 14 позиций
[2021-04-18 11:25:20,482] [WARNING] => Not Found: /persons/position1
[2021-04-18 11:25:50,625] [WARNING] => Not Found: /persons/person2
[2021-04-18 11:40:33,550] [WARNING] => Not Found: /favicon.ico
[2021-04-18 12:33:15,549] [WARNING] => Not Found: /favicon.ico
